Workbook
Name SEC_H: SECT!$A$2:$A$60
Name SEC_R: TUBE!$A$2:$A$154

Sheet PARAM
B1: COLUMN
B2: Three pieces and a splice where two of them meet. Fill in the blue cells — the input tab is written from this one.
B4: 1. SECTION | C4: Type decides which list the Section cell offers — H sections, or square tubes
C5: Type | D5: Section | E5: h | F5: b | G5: tw / t | H5: tf | I5: r | J5: Alpha | K5: kg/m
B6: Column | C6: H | D6: H-300x300x10x15 r18 | E6: =IF(PARAM!$C$6="H",IFERROR(VLOOKUP($D$6,SECT!$A:$G,2,FALSE),""),IFERROR(VLOOKUP($D$6,TUBE!$A:$G,2,FALSE),"")) -> 300 | F6: =IF(PARAM!$C$6="H",IFERROR(VLOOKUP($D$6,SECT!$A:$G,3,FALSE),""),IFERROR(VLOOKUP($D$6,TUBE!$A:$G,3,FALSE),"")) -> 300 | G6: =IF(PARAM!$C$6="H",IFERROR(VLOOKUP($D$6,SECT!$A:$G,4,FALSE),""),IFERROR(VLOOKUP($D$6,TUBE!$A:$G,4,FALSE),"")) -> 10 | H6: =IF(PARAM!$C$6="H",IFERROR(VLOOKUP($D$6,SECT!$A:$G,5,FALSE),""),IFERROR(VLOOKUP($D$6,TUBE!$A:$G,5,FALSE),"")) -> 15 | I6: =IF(PARAM!$C$6="H",IFERROR(VLOOKUP($D$6,SECT!$A:$G,6,FALSE),""),IFERROR(VLOOKUP($D$6,TUBE!$A:$G,6,FALSE),"")) -> 18 | J6: 0 | K6: =IF(PARAM!$C$6="H",IFERROR(VLOOKUP($D$6,SECT!$A:$G,7,FALSE),""),IFERROR(VLOOKUP($D$6,TUBE!$A:$G,7,FALSE),"")) -> 94
B7: Length | D7: upper | E7: 700 | F7: middle | G7: 1400 | H7: lower | I7: 700
B8: Steel | C8: SS275 | E8: put 0 in upper or lower if you do not want that piece — its splice goes with it
B9: Pick "user define" at the top of either list and the five cells go blank — type over them. A tube has no flange, so its wall goes in tw and tf alike.
B10: Alpha turns the whole column about its axis, plates and bolts with it. 0 faces the flanges along X, ±90 along Y; a tube looks alike either way.
B11: checked for you | C11: section | D11: =IF(PARAM!$E$6="","fill in the dimensions","ok") -> ok | E11: splices | F11: =(IF(PARAM!$E$7>0,1,0)+IF(PARAM!$I$7>0,1,0))&" of 2" -> 2 of 2 | G11: flanges face | H11: =IF(PARAM!$C$6="H",IF(MOD(PARAM!$J$6,180)=0,"X","Y"),"all four alike") -> X
B13: 2. SPLICE PLATES | C13: cover plates on an H, an end plate on a tube — Type keeps whichever the section calls for
E14: Width | F14: Length | G14: Thick | H14: Qty | I14: Material | J14: gap / over
B15: Flange plate | E15: 300 | F15: 330 | G15: 12 | H15: 2 | I15: SS275 | J15: 10 | K15: Type H
B16: Flange inner plate | E16: 110 | F16: 330 | G16: 10 | H16: 4 | I16: SS275 | K16: Type H
B17: Web plate | E17: 234 | F17: 330 | G17: 10 | H17: 2 | I17: SS275 | K17: Type H
B18: End plate | E18: =PARAM!$E$6+2*PARAM!$J$18 -> 420 | F18: =PARAM!$F$6+2*PARAM!$J$18 -> 420 | G18: 20 | H18: 2 | I18: SS275 | J18: 60 | K18: Type R
B19: Width is across the flange or through the web; Length runs along the column. The end plate follows the section, plus 60 all round.
B20: checked for you | C20: in use | D20: =IF(PARAM!$C$6="H","cover plates","end plate") -> cover plates | E20: plate steel, kg | F20: =ROUND(IF(PARAM!$C$6="H",PARAM!$E$15*PARAM!$F$15*PARAM!$G$15*2+PARAM!$E$16*PARAM!$F$16*PARAM!$G$16*4+PARAM!$E$17*PARAM!$F$17*PARAM!$G$17*2,PARAM!$E$18*PARAM!$F$18*PARAM!$G$18*2)*7.85/1000000,1) -> 42.2 | G20: plates fit | H20: =IF(PARAM!$C$6="H",IF(AND(PARAM!$E$15<=PARAM!$F$6,PARAM!$E$17<=PARAM!$E$6-2*PARAM!$H$6-2*PARAM!$I$6),"ok",IF(PARAM!$E$15>PARAM!$F$6,"flange plate too wide","web plate too deep")),"n/a") -> ok
B22: 3. BOLTS | C22: the shank and the hole are different sizes, and each grip gets its own length
E23: dia | F23: hole | G23: grade | H23: flange L | I23: web L | J23: end L
B24: Bolt | E24: 16 | F24: =PARAM!$E$24+2 -> 18 | G24: F10T | H24: =IF(PARAM!$C$6="H",CEILING(PARAM!$G$15+PARAM!$H$6+PARAM!$G$16+1.1*PARAM!$E$24,5),"—") -> 55 | I24: =IF(PARAM!$C$6="H",CEILING(PARAM!$G$6+2*PARAM!$G$17+1.1*PARAM!$E$24,5),"—") -> 50 | J24: =IF(PARAM!$C$6="H","—",CEILING(2*PARAM!$G$18+1.1*PARAM!$E$24,5)) -> —
B25: bolt group | E25: Long N | F25: In | G25: Out | H25: Trans N | I25: In | J25: Out
B26: Flange | E26: 4 | F26: 70 | G26: 45 | H26: 4 | I26: 100 | J26: 40
B27: Web | E27: 4 | F27: 60 | G27: 45 | H27: 3 | I27: 0 | J27: 40
E28: Width N | F28: Out | H28: Length N | I28: Out
B29: End plate | E29: 3 | F29: 30 | H29: 3 | I29: 30
B30: Flange and Web: Long is along the column, Trans across it. End plate: how many bolts down each side of the plate, and Out from its edge.
B31: checked for you | C31: flange pitch | D31: =IF(PARAM!$C$6="H",ROUND((PARAM!$F$15/2-PARAM!$G$26-PARAM!$F$26/2)/(PARAM!$E$26/2-1),1)&" / "&ROUND((PARAM!$E$15/2-PARAM!$J$26-PARAM!$I$26/2)/(PARAM!$H$26/2-1),1),"n/a") -> 85 / 60 | E31: web pitch | F31: =IF(PARAM!$C$6="H",ROUND((PARAM!$F$17/2-PARAM!$G$27-PARAM!$F$27/2)/(PARAM!$E$27/2-1),1)&" / "&ROUND((PARAM!$E$17-2*PARAM!$J$27-PARAM!$I$27)/(PARAM!$H$27-1),1),"n/a") -> 90 / 77 | G31: bolts | H31: =IF(PARAM!$C$6="H",2*PARAM!$E$26*PARAM!$H$26+PARAM!$E$27*PARAM!$H$27,2*PARAM!$E$29+2*MAX(0,PARAM!$H$29-2))&" per splice" -> 44 per splice
B33: 4. BEAMS | C33: four world directions - X+ X- Y+ Y-. Length 0 and that beam is not there
C34: Detail | D34: Section | E34: h | F34: b | G34: tw | H34: tf | I34: r | J34: Length | K34: kg/m
B35: X+ | C35: C1 | D35: H-300x150x6.5x9 r13 | E35: =IFERROR(VLOOKUP($D$35,SECT!$A:$G,2,FALSE),"") -> 300 | F35: =IFERROR(VLOOKUP($D$35,SECT!$A:$G,3,FALSE),"") -> 150 | G35: =IFERROR(VLOOKUP($D$35,SECT!$A:$G,4,FALSE),"") -> 6.5 | H35: =IFERROR(VLOOKUP($D$35,SECT!$A:$G,5,FALSE),"") -> 9 | I35: =IFERROR(VLOOKUP($D$35,SECT!$A:$G,6,FALSE),"") -> 13 | J35: 900 | K35: =IFERROR(VLOOKUP($D$35,SECT!$A:$G,7,FALSE),"") -> 36.7
B36: X- | C36: C3 | D36: H-300x150x6.5x9 r13 | E36: =IFERROR(VLOOKUP($D$36,SECT!$A:$G,2,FALSE),"") -> 300 | F36: =IFERROR(VLOOKUP($D$36,SECT!$A:$G,3,FALSE),"") -> 150 | G36: =IFERROR(VLOOKUP($D$36,SECT!$A:$G,4,FALSE),"") -> 6.5 | H36: =IFERROR(VLOOKUP($D$36,SECT!$A:$G,5,FALSE),"") -> 9 | I36: =IFERROR(VLOOKUP($D$36,SECT!$A:$G,6,FALSE),"") -> 13 | J36: 900 | K36: =IFERROR(VLOOKUP($D$36,SECT!$A:$G,7,FALSE),"") -> 36.7
B37: Y+ | C37: C3 | D37: H-300x150x6.5x9 r13 | E37: =IFERROR(VLOOKUP($D$37,SECT!$A:$G,2,FALSE),"") -> 300 | F37: =IFERROR(VLOOKUP($D$37,SECT!$A:$G,3,FALSE),"") -> 150 | G37: =IFERROR(VLOOKUP($D$37,SECT!$A:$G,4,FALSE),"") -> 6.5 | H37: =IFERROR(VLOOKUP($D$37,SECT!$A:$G,5,FALSE),"") -> 9 | I37: =IFERROR(VLOOKUP($D$37,SECT!$A:$G,6,FALSE),"") -> 13 | J37: 900 | K37: =IFERROR(VLOOKUP($D$37,SECT!$A:$G,7,FALSE),"") -> 36.7
B38: Y- | C38: C3 | D38: H-300x150x6.5x9 r13 | E38: =IFERROR(VLOOKUP($D$38,SECT!$A:$G,2,FALSE),"") -> 300 | F38: =IFERROR(VLOOKUP($D$38,SECT!$A:$G,3,FALSE),"") -> 150 | G38: =IFERROR(VLOOKUP($D$38,SECT!$A:$G,4,FALSE),"") -> 6.5 | H38: =IFERROR(VLOOKUP($D$38,SECT!$A:$G,5,FALSE),"") -> 9 | I38: =IFERROR(VLOOKUP($D$38,SECT!$A:$G,6,FALSE),"") -> 13 | J38: 0 | K38: =IFERROR(VLOOKUP($D$38,SECT!$A:$G,7,FALSE),"") -> 36.7
B39: Beams are H only: a tube has no web to bolt through. The direction is the world's, so Alpha decides whether a beam lands on a flange or on the web.
B40: checked for you | C40: X faces | D40: =IF(PARAM!$C$6="H",IF(MOD(PARAM!$J$6,180)=0,"flange","web"),"tube wall") -> flange | E40: Y faces | F40: =IF(PARAM!$C$6="H",IF(MOD(PARAM!$J$6,180)=0,"web","flange"),"tube wall") -> web | G40: beams | H40: =(IF(PARAM!$J$35>0,1,0)+IF(PARAM!$J$36>0,1,0)+IF(PARAM!$J$37>0,1,0)+IF(PARAM!$J$38>0,1,0))&" of 4" -> 3 of 4
B42: 5. CONNECTION | C42: declare them here, then name one against each beam above — end plate bolts through the column, fin plate through the beam web
C43: Type | D43: what it is | E43: setback | F43: width | G43: height | H43: thick | I43: gauge | J43: edge | K43: pitch | L43: count
B44: C1 | C44: end plate | D44: 3 rows, through the col | E44: 0 | F44: 230 | G44: =K44*(L44-1)+2*J44 -> 230 | H44: 20 | I44: 140 | J44: 45 | K44: 70 | L44: 3
B45: C2 | C45: end plate | D45: 4 rows, for a deep beam | E45: 0 | F45: 230 | G45: =K45*(L45-1)+2*J45 -> 300 | H45: 20 | I45: 140 | J45: 45 | K45: 70 | L45: 4
...

Sheet input
A1: Written from PARAM. Nothing here needs editing — change the front sheet instead.
B2: COORD | C2: ZUP
A4: SECT id material length TYPE base.pt v1..v7 an H takes seven values, a tube four — the last three go blank by formula
A5: MAX(1,..) keeps the definition alive when its piece is switched off below: a SECT of length 0 is not defined at all, and the MODULE naming it then fails.
A6: upper | B6: SECT | C6: sc.c1 | D6: =PARAM!$C$8 -> SS275 | E6: =MAX(1,PARAM!$E$7) -> 700 | F6: =IF(PARAM!$C$6="H","H","R") -> H | G6: mc | H6: =PARAM!$E$6 -> 300 | I6: =PARAM!$F$6 -> 300 | J6: =IF(PARAM!$C$6="H",PARAM!$F$6,PARAM!$G$6) -> 300 | K6: =IF(PARAM!$C$6="H",PARAM!$G$6,PARAM!$I$6) -> 10 | L6: =IF(PARAM!$C$6="H",PARAM!$H$6,"") -> 15 | M6: =IF(PARAM!$C$6="H",PARAM!$H$6,"") -> 15 | N6: =IF(PARAM!$C$6="H",PARAM!$I$6,"") -> 18
A7: middle | B7: SECT | C7: sc.c2 | D7: =PARAM!$C$8 -> SS275 | E7: =MAX(1,PARAM!$G$7) -> 1400 | F7: =IF(PARAM!$C$6="H","H","R") -> H | G7: mc | H7: =PARAM!$E$6 -> 300 | I7: =PARAM!$F$6 -> 300 | J7: =IF(PARAM!$C$6="H",PARAM!$F$6,PARAM!$G$6) -> 300 | K7: =IF(PARAM!$C$6="H",PARAM!$G$6,PARAM!$I$6) -> 10 | L7: =IF(PARAM!$C$6="H",PARAM!$H$6,"") -> 15 | M7: =IF(PARAM!$C$6="H",PARAM!$H$6,"") -> 15 | N7: =IF(PARAM!$C$6="H",PARAM!$I$6,"") -> 18
A8: lower | B8: SECT | C8: sc.c3 | D8: =PARAM!$C$8 -> SS275 | E8: =MAX(1,PARAM!$I$7) -> 700 | F8: =IF(PARAM!$C$6="H","H","R") -> H | G8: mc | H8: =PARAM!$E$6 -> 300 | I8: =PARAM!$F$6 -> 300 | J8: =IF(PARAM!$C$6="H",PARAM!$F$6,PARAM!$G$6) -> 300 | K8: =IF(PARAM!$C$6="H",PARAM!$G$6,PARAM!$I$6) -> 10 | L8: =IF(PARAM!$C$6="H",PARAM!$H$6,"") -> 15 | M8: =IF(PARAM!$C$6="H",PARAM!$H$6,"") -> 15 | N8: =IF(PARAM!$C$6="H",PARAM!$I$6,"") -> 18
A10: PLATE / BOLT — pl.fo is the flange cover plate on an H and the end plate on a tube; the inner and web plates are switched off on a tube, and so are the bolts that hold them.
A11: flange plate, or end plate | B11: PLATE | C11: pl.fo | D11: =PARAM!$C$8 -> SS275 | E11: =IF(PARAM!$C$6="H",PARAM!$G$15,PARAM!$G$18) -> 12 | F11: RECT | G11: mc | H11: =IF(PARAM!$C$6="H",PARAM!$E$15,PARAM!$E$18) -> 300 | I11: =IF(PARAM!$C$6="H",PARAM!$F$15,PARAM!$F$18) -> 330
A12: flange inner plate, x4 — H only | B12: PLATE | C12: pl.fi | D12: =PARAM!$C$8 -> SS275 | E12: =PARAM!$G$16 -> 10 | F12: RECT | G12: mc | H12: =PARAM!$E$16 -> 110 | I12: =PARAM!$F$16 -> 330
A13: web plate, x2 — H only | B13: PLATE | C13: pl.wp | D13: =PARAM!$C$8 -> SS275 | E13: =PARAM!$G$17 -> 10 | F13: RECT | G13: mc | H13: =PARAM!$E$17 -> 234 | I13: =PARAM!$F$17 -> 330
A14: flange bolt, or end plate bolt | B14: BOLT | C14: bo.f | D14: =PARAM!$G$24 -> F10T | E14: =PARAM!$E$24 -> 16 | F14: =IF(PARAM!$C$6="H",PARAM!$H$24,PARAM!$J$24) -> 55 | G14: =PARAM!$F$24 -> 18 | K14: =0.9*PARAM!$E$24 -> 14.4 | L14: =IF(PARAM!$C$6="H",PARAM!$H$24-PARAM!$G$15-PARAM!$H$6-PARAM!$G$16,PARAM!$J$24-2*PARAM!$G$18)-0.9*PARAM!$E$24 -> 3.6
A15: web bolt — H only | B15: BOLT | C15: bo.w | D15: =PARAM!$G$24 -> F10T | E15: =PARAM!$E$24 -> 16 | F15: =IF(PARAM!$C$6="H",PARAM!$I$24,1) -> 50 | G15: =PARAM!$F$24 -> 18 | K15: =0.9*PARAM!$E$24 -> 14.4 | L15: =IF(PARAM!$C$6="H",PARAM!$I$24-PARAM!$G$6-2*PARAM!$G$17-0.9*PARAM!$E$24,0) -> 5.6
A17: the stiffeners, one plate per level. RECT takes B then H: B runs along the column's h and is the DEPTH between the flanges, H runs along b and is the WIDTH out from the web.
A18: MAX(1,..) once more — a plate of zero size is not defined at all, and the MODULE naming it would then fail rather than quietly skip.
A19: level 1 — every row of chapter 6 gets one of these | B19: PLATE | C19: pl.stf1 | D19: =PARAM!$C$8 -> SS275 | E19: =MAX(1,PARAM!$H$55) -> 12 | F19: RECT | G19: mc | H19: =MAX(1,PARAM!$G$55) -> 270 | I19: =MAX(1,PARAM!$F$55) -> 145
B20: PLATE | C20: pl.stf2 | D20: =PARAM!$C$8 -> SS275 | E20: =MAX(1,PARAM!$H$56) -> 12 | F20: RECT | G20: mc | H20: =MAX(1,PARAM!$G$56) -> 270 | I20: =MAX(1,PARAM!$F$56) -> 145
B21: PLATE | C21: pl.stf3 | D21: =PARAM!$C$8 -> SS275 | E21: =MAX(1,PARAM!$H$57) -> 1 | F21: RECT | G21: mc | H21: =MAX(1,PARAM!$G$57) -> 1 | I21: =MAX(1,PARAM!$F$57) -> 1
B22: PLATE | C22: pl.stf4 | D22: =PARAM!$C$8 -> SS275 | E22: =MAX(1,PARAM!$H$58) -> 1 | F22: RECT | G22: mc | H22: =MAX(1,PARAM!$G$58) -> 1 | I22: =MAX(1,PARAM!$F$58) -> 1
B23: PLATE | C23: pl.stf5 | D23: =PARAM!$C$8 -> SS275 | E23: =MAX(1,PARAM!$H$59) -> 1 | F23: RECT | G23: mc | H23: =MAX(1,PARAM!$G$59) -> 1 | I23: =MAX(1,PARAM!$F$59) -> 1
B24: PLATE | C24: pl.stf6 | D24: =PARAM!$C$8 -> SS275 | E24: =MAX(1,PARAM!$H$60) -> 1 | F24: RECT | G24: mc | H24: =MAX(1,PARAM!$G$60) -> 1 | I24: =MAX(1,PARAM!$F$60) -> 1
B25: PLATE | C25: pl.stf7 | D25: =PARAM!$C$8 -> SS275 | E25: =MAX(1,PARAM!$H$61) -> 1 | F25: RECT | G25: mc | H25: =MAX(1,PARAM!$G$61) -> 1 | I25: =MAX(1,PARAM!$F$61) -> 1
B26: PLATE | C26: pl.stf8 | D26: =PARAM!$C$8 -> SS275 | E26: =MAX(1,PARAM!$H$62) -> 1 | F26: RECT | G26: mc | H26: =MAX(1,PARAM!$G$62) -> 1 | I26: =MAX(1,PARAM!$F$62) -> 1
A28: MODULE id member Ref.Pt L.X L.Y L.Z PLANE [ROT.X ROT.Y ROT.Z] [dx dy dz repeat] [dx2 dy2 dz2 repeat2]
A29: ROT.Z 90 turns the section so its h runs along X. A square column cannot show that in a bounding box, so it is written down rather than looked for.
A30: a blank member is simply not there — which is how a length of 0 removes a piece | B30: MODULE | C30: md.c1 | D30: =IF(PARAM!$E$7>0,"sc.c1","") -> sc.c1 | F30: 0 | G30: 0 | H30: 0 | I30: XY | J30: 0 | K30: 0 | L30: 90
B31: MODULE | C31: md.c1 | D31: BASE | E31: sc.c1 | F31: mc
B32: MODULE | C32: md.c2 | D32: ="sc.c2" -> sc.c2 | F32: 0 | G32: 0 | H32: 0 | I32: XY | J32: 0 | K32: 0 | L32: 90
B33: MODULE | C33: md.c2 | D33: BASE | E33: sc.c2 | F33: mc
B34: MODULE | C34: md.c3 | D34: =IF(PARAM!$I$7>0,"sc.c3","") -> sc.c3 | F34: 0 | G34: 0 | H34: 0 | I34: XY | J34: 0 | K34: 0 | L34: 90
B35: MODULE | C35: md.c3 | D35: BASE | E35: sc.c3 | F35: mc
A37: The splice, its origin the middle of the joint. Every quadrant of a bolt group is one row: the two repeat axes reach across the flange and along the column, and the four sign combinations are the four corners of the pattern.
A38: flange plate on each flange — or, on a tube, the two end plates | B38: MODULE | C38: md.spu | D38: =IF(PARAM!$E$7>0,"pl.fo","") -> pl.fo | E38: mc | F38: =IF(PARAM!$C$6="H",((PARAM!$E$6/2+PARAM!$G$15/2)),0) -> 156 | G38: 0 | H38: =IF(PARAM!$C$6="H",0,(PARAM!$G$18/2)) -> 0 | I38: =IF(PARAM!$C$6="H","YZ","XY") -> YZ
B39: MODULE | C39: md.spu | D39: =IF(PARAM!$E$7>0,"pl.fo","") -> pl.fo | E39: mc | F39: =IF(PARAM!$C$6="H",-((PARAM!$E$6/2+PARAM!$G$15/2)),0) -> -156 | G39: 0 | H39: =IF(PARAM!$C$6="H",0,-(PARAM!$G$18/2)) -> 0 | I39: =IF(PARAM!$C$6="H","YZ","XY") -> YZ
A40: inner plates, each centred on its own two bolt lines | B40: MODULE | C40: md.spu | D40: =IF(AND(PARAM!$E$7>0,PARAM!$C$6="H"),"pl.fi","") -> pl.fi | E40: mc | F40: =((PARAM!$E$6/2-PARAM!$H$6-PARAM!$G$16/2)) -> 130 | G40: =((PARAM!$I$26/2+((PARAM!$E$15/2-PARAM!$J$26-PARAM!$I$26/2)/(PARAM!$H$26/2-1))/2)) -> 80 | H40: 0 | I40: YZ
B41: MODULE | C41: md.spu | D41: =IF(AND(PARAM!$E$7>0,PARAM!$C$6="H"),"pl.fi","") -> pl.fi | E41: mc | F41: =((PARAM!$E$6/2-PARAM!$H$6-PARAM!$G$16/2)) -> 130 | G41: =-((PARAM!$I$26/2+((PARAM!$E$15/2-PARAM!$J$26-PARAM!$I$26/2)/(PARAM!$H$26/2-1))/2)) -> -80 | H41: 0 | I41: YZ
B42: MODULE | C42: md.spu | D42: =IF(AND(PARAM!$E$7>0,PARAM!$C$6="H"),"pl.fi","") -> pl.fi | E42: mc | F42: =-((PARAM!$E$6/2-PARAM!$H$6-PARAM!$G$16/2)) -> -130 | G42: =((PARAM!$I$26/2+((PARAM!$E$15/2-PARAM!$J$26-PARAM!$I$26/2)/(PARAM!$H$26/2-1))/2)) -> 80 | H42: 0 | I42: YZ
B43: MODULE | C43: md.spu | D43: =IF(AND(PARAM!$E$7>0,PARAM!$C$6="H"),"pl.fi","") -> pl.fi | E43: mc | F43: =-((PARAM!$E$6/2-PARAM!$H$6-PARAM!$G$16/2)) -> -130 | G43: =-((PARAM!$I$26/2+((PARAM!$E$15/2-PARAM!$J$26-PARAM!$I$26/2)/(PARAM!$H$26/2-1))/2)) -> -80 | H43: 0 | I43: YZ
A44: web plate, one each side | B44: MODULE | C44: md.spu | D44: =IF(AND(PARAM!$E$7>0,PARAM!$C$6="H"),"pl.wp","") -> pl.wp | E44: mc | F44: 0 | G44: =((PARAM!$G$6/2+PARAM!$G$17/2)) -> 10 | H44: 0 | I44: XZ
B45: MODULE | C45: md.spu | D45: =IF(AND(PARAM!$E$7>0,PARAM!$C$6="H"),"pl.wp","") -> pl.wp | E45: mc | F45: 0 | G45: =-((PARAM!$G$6/2+PARAM!$G$17/2)) -> -10 | H45: 0 | I45: XZ
...

Sheet SECT
A1: Section | B1: h | C1: b | D1: tw | E1: tf | F1: r | G1: kg/m
A2: user define
A3: H-100x100x6x8 r10 | B3: 100 | C3: 100 | D3: 6 | E3: 8 | F3: 10 | G3: 17.2
A4: H-125x125x6.5x9 r10 | B4: 125 | C4: 125 | D4: 6.5 | E4: 9 | F4: 10 | G4: 23.8
A5: H-150x75x5x7 r8 | B5: 150 | C5: 75 | D5: 5 | E5: 7 | F5: 8 | G5: 14
A6: H-148x100x6x9 r11 | B6: 148 | C6: 100 | D6: 6 | E6: 9 | F6: 11 | G6: 21.1
A7: H-150x150x7x10 r11 | B7: 150 | C7: 150 | D7: 7 | E7: 10 | F7: 11 | G7: 31.5
A8: H-198x99x4.5x7 r11 | B8: 198 | C8: 99 | D8: 4.5 | E8: 7 | F8: 11 | G8: 18.2
A9: H-200x100x5.5x8 r11 | B9: 200 | C9: 100 | D9: 5.5 | E9: 8 | F9: 11 | G9: 21.3
A10: H-194x150x6x9 r13 | B10: 194 | C10: 150 | D10: 6 | E10: 9 | F10: 13 | G10: 30.6
A11: H-200x200x8x12 r13 | B11: 200 | C11: 200 | D11: 8 | E11: 12 | F11: 13 | G11: 49.9
A12: H-200x204x12x12 r13 | B12: 200 | C12: 204 | D12: 12 | E12: 12 | F12: 13 | G12: 56.2
A13: H-248x124x5x8 r12 | B13: 248 | C13: 124 | D13: 5 | E13: 8 | F13: 12 | G13: 25.7
A14: H-250x125x6x9 r12 | B14: 250 | C14: 125 | D14: 6 | E14: 9 | F14: 12 | G14: 29.6
... A60: H-918x303x19x37 r18 | B60: 918 | C60: 303 | D60: 19 | E60: 37 | F60: 18 | G60: 304

Sheet TUBE
A1: Section | B1: h | C1: b | D1: tw | E1: tf | F1: r | G1: kg/m
A2: user define
A3: R-20x20x1.2 r2.4 | B3: 20 | C3: 20 | D3: 1.2 | E3: 1.2 | F3: 2.4 | G3: 0.68
A4: R-20x20x1.6 r3.2 | B4: 20 | C4: 20 | D4: 1.6 | E4: 1.6 | F4: 3.2 | G4: 0.87
A5: R-25x25x1.2 r2.4 | B5: 25 | C5: 25 | D5: 1.2 | E5: 1.2 | F5: 2.4 | G5: 0.87
A6: R-25x25x1.6 r3.2 | B6: 25 | C6: 25 | D6: 1.6 | E6: 1.6 | F6: 3.2 | G6: 1.12
A7: R-30x30x1.2 r2.4 | B7: 30 | C7: 30 | D7: 1.2 | E7: 1.2 | F7: 2.4 | G7: 1.06
A8: R-30x30x1.6 r3.2 | B8: 30 | C8: 30 | D8: 1.6 | E8: 1.6 | F8: 3.2 | G8: 1.38
A9: R-40x40x1.6 r3.2 | B9: 40 | C9: 40 | D9: 1.6 | E9: 1.6 | F9: 3.2 | G9: 1.88
A10: R-40x40x2.3 r4.6 | B10: 40 | C10: 40 | D10: 2.3 | E10: 2.3 | F10: 4.6 | G10: 2.62
A11: R-50x50x1.6 r3.2 | B11: 50 | C11: 50 | D11: 1.6 | E11: 1.6 | F11: 3.2 | G11: 2.38
A12: R-50x50x2.3 r4.6 | B12: 50 | C12: 50 | D12: 2.3 | E12: 2.3 | F12: 4.6 | G12: 3.34
A13: R-50x50x3.2 r6.4 | B13: 50 | C13: 50 | D13: 3.2 | E13: 3.2 | F13: 6.4 | G13: 4.5
A14: R-60x60x1.6 r3.2 | B14: 60 | C14: 60 | D14: 1.6 | E14: 1.6 | F14: 3.2 | G14: 2.88
... A154: R-800x800x40 r140 | B154: 800 | C154: 800 | D154: 40 | E154: 40 | F154: 140 | G154: 889.87
