Workbook

Sheet PARAM
B1: TOWER CRANE
B2: Fill in the blue cells. Everything else follows — the input tab is written from this one, and nothing on it needs touching.
B4: 1. MAST | C4: how tall the tower stands — panel count is the height
C5: Panel ht | D5: Panels | E5: Foot lvl | F5: A-frame ht | H5: Mast top | I5: Apex | J5: Overall
B6: Mast | C6: 2400 | D6: 15 | E6: 1000 | F6: 9630 | H6: ==PARAM!$E$6+PARAM!$C$6*PARAM!$D$6 -> 37000 | I6: ==PARAM!$H$6+370+PARAM!$F$6 -> 47000 | J6: ==PARAM!$I$6+860 -> 47860
B7: Panels is the only cell that changes the height — the slewing deck, the tower head, the jib, the counter-jib and the hoist all ride on Mast top. Head ht is measured from the deck to the apex, so the A-frame keeps its shape at any tower height.
B8: checked for you | C8: panels | D8: ==IF(PARAM!$D$6<3,"at least 3",IF(PARAM!$D$6>40,"over 40 — free-standing?","ok "&PARAM!$D$6)) -> ok 15 | E8: overall | F8: ==TEXT(PARAM!$J$6/1000,"0.0")&" m" -> 47.9 m
B10: 2. JIB AND TAIL | C10: how far it reaches — bay count is the radius
C11: Bay | D11: Bays | E11: Root | F11: Tip | H11: End | I11: Radius | J11: Bottom chord
B12: Jib | C12: 3000 | D12: 15 | E12: 1900 | F12: 1600 | H12: ==PARAM!$E$12+PARAM!$C$12*PARAM!$D$12 -> 46900 | I12: ==PARAM!$H$12+PARAM!$F$12 -> 48500 | J12: ==PARAM!$H$6+1140 -> 38140
B13: Counter-jib | C13: 2600 | D13: 5 | E13: 1900 | F13: — | H13: ==-PARAM!$E$13-PARAM!$C$13*PARAM!$D$13 -> -14900 | I13: ==-PARAM!$H$13 -> 14900
B14: Bays is the only cell that changes the reach. The jib tip module, the pendant hang points and the trolley limit are all worked out from End — nothing on the input tab is written to a fixed radius.
B15: checked for you | C15: pendant at | D15: ==TEXT(PARAM!$E$12+PARAM!$C$12*ROUND((PARAM!$D$12-2)/2,0),"0")&" / "&TEXT(PARAM!$H$12-1500,"0") -> 21400 / 45400 | E15: radius | F15: ==TEXT(PARAM!$I$12/1000,"0.0")&" m" -> 48.5 m
B17: 3. HOIST | C17: where the trolley parks and how far the hook hangs
C18: Trolley R | D18: Hook drop | H18: Trolley lvl | I18: Hook lvl | J18: Ground clr
B19: Hoist | C19: 30000 | D19: 26020 | H19: ==PARAM!$J$12+1880 -> 40020 | I19: ==PARAM!$H$19-PARAM!$D$19 -> 14000 | J19: ==PARAM!$I$19-1910 -> 12090
B20: Hook drop is the rope, measured down from the trolley — so the hook keeps the same drop when the tower grows, which is what you want when the two are animated together. Both the hook module and the four falls of rope read this one cell.
B21: checked for you | C21: trolley | D21: ==IF(PARAM!$C$19>PARAM!$H$12-1500,"past the jib end","ok") -> ok | E21: hook | F21: ==IF(PARAM!$J$19<0,"below ground by "&TEXT(-PARAM!$J$19/1000,"0.0")&" m","ok") -> ok
B23: 4. JIB SLEW | C23: which way the jib points — the mast stays put
C24: Jib angle ° | H24: cos | I24: sin | J24: Jib points
B25: Jib slew | C25: 0 | H25: ==COS(RADIANS(PARAM!$C$25)) -> 1 | I25: ==SIN(RADIANS(PARAM!$C$25)) -> 0 | J25: ==TEXT(MOD(PARAM!$C$25,360),"0")&"° from +X" -> 0° from +X
B26: The jib turns, and everything that rides with it: counter-jib, counterweight, tower head, cab, machinery deck, pendants, trolley and hook — the slewing deck and all of it above the bearing. The base and the mast do not move. The axis is the mast centre line, so 0 deg is the jib along +X.
B28: 5. WHAT THE NUMBERS MEAN | C28: the same cells, drawn where they act
B30: Elevation — every blue cell, dimensioned where it acts
B69: Plan — the jib angle, drawn here at 40°

Sheet input
A1: Saddle-jib tower crane. Every teal number is read from the PARAM tab - change it there, not here. | B1: # SECT | C1: id | D1: mat | E1: length | F1: TYPE | G1: base.pt | H1: v1 | I1: v2 | J1: v3 | K1: v4 | L1: v5 | M1: v6 | N1: v7
A2: mast chord. The length here is the panel; the coordinates rule | B2: SECT | C2: sc.mch | D2: SM490 | E2: ==PARAM!$C$6 -> 2400 | F2: L | G2: bl | H2: 150 | I2: 150 | J2: 14 | K2: 14 | L2: 14 | M2: 7
B3: SECT | C3: sc.jch | D3: SM490 | E3: ==PARAM!$C$12 -> 3000 | F3: L | G3: bl | H3: 120 | I3: 120 | J3: 12 | K3: 12 | L3: 12 | M3: 6
B4: SECT | C4: sc.cch | D4: SM490 | E4: ==PARAM!$C$13 -> 2600 | F4: L | G4: bl | H4: 110 | I4: 110 | J4: 10 | K4: 10 | L4: 10 | M4: 5
A5: tower head leg - leans two ways, so it is written as two points | B5: SECT | C5: sc.hlg | D5: SM490 | E5: 9500 | F5: L | G5: bl | H5: 130 | I5: 130 | J5: 12 | K5: 12 | L5: 12 | M5: 6
B6: SECT | C6: sc.main | D6: SM490 | E6: 4600 | F6: H | G6: mc | H6: 700 | I6: 300 | J6: 300 | K6: 14 | L6: 22 | M6: 22 | N6: 24
B7: SECT | C7: sc.bfr | D7: SM490 | E7: 4800 | F7: H | G7: mc | H7: 600 | I7: 250 | J7: 250 | K7: 12 | L7: 19 | M7: 19 | N7: 22
B8: SECT | C8: sc.bcr | D8: SM490 | E8: 1400 | F8: H | G8: mc | H8: 400 | I8: 200 | J8: 200 | K8: 9 | L8: 14 | M8: 14 | N8: 16
B10: # BAR | C10: id | D10: mat | E10: dia | F10: length
B11: BAR | C11: bar.mh | D11: SM490 | E11: 70 | F11: 1600
B12: BAR | C12: bar.md | D12: SM490 | E12: 60 | F12: 2885
B13: BAR | C13: bar.lst | D13: SS275 | E13: 34 | F13: ==PARAM!$C$6 -> 2400
B14: BAR | C14: bar.lrg | D14: SS275 | E14: 22 | F14: 400
B15: BAR | C15: bar.strut | D15: SM490 | E15: 130 | F15: 4300
B16: BAR | C16: bar.anb | D16: SS400 | E16: 48 | F16: 180
A17: jib bottom chord | B17: BAR | C17: bar.jbc | D17: SM490 | E17: 100 | F17: ==PARAM!$C$12 -> 3000
B18: BAR | C18: bar.jth | D18: SM490 | E18: 70 | F18: 1300
B19: BAR | C19: bar.jw | D19: SM490 | E19: 60 | F19: 2200
B20: BAR | C20: bar.jpl | D20: SM490 | E20: 55 | F20: 3300
B21: BAR | C21: bar.cbc | D21: SM490 | E21: 110 | F21: ==PARAM!$C$13 -> 2600
B22: BAR | C22: bar.ch | D22: SM490 | E22: 65 | F22: 1300
B23: BAR | C23: bar.cw | D23: SM490 | E23: 60 | F23: 2000
B24: BAR | C24: bar.ht | D24: SM490 | E24: 70 | F24: 1600
B25: BAR | C25: bar.hd | D25: SM490 | E25: 60 | F25: 2400
A26: pendant tie bar | B26: BAR | C26: bar.pen | D26: SS540 | E26: 70 | F26: 26000
B27: BAR | C27: bar.hang | D27: SM490 | E27: 80 | F27: 800
B28: BAR | C28: bar.rope | D28: SS275 | E28: 26 | F28: 26000
B29: BAR | C29: bar.rail | D29: SS275 | E29: 34 | F29: 4800
B30: BAR | C30: bar.post | D30: SS275 | E30: 40 | F30: 1050
B31: BAR | C31: bar.shk | D31: SM490 | E31: 150 | F31: 700
B32: BAR | C32: bar.axle | D32: SM490 | E32: 90 | F32: 900
B33: BAR | C33: bar.barrel | D33: SM490 | E33: 420 | F33: 1300
B35: # PLATE | C35: id | D35: mat | E35: thk | F35: shape | G35: base.pt | H35: p1 | I35: p2 | J35: p3 | K35: p4
B36: PLATE | C36: pl.bped | D36: SM490 | E36: 50 | F36: RECT | G36: mc | H36: 1900 | I36: 1900
B37: PLATE | C37: pl.fpl | D37: SM490 | E37: 60 | F37: RECT | G37: mc | H37: 900 | I37: 900
B38: PLATE | C38: pl.ring | D38: SM490 | E38: 120 | F38: CIRC | G38: mc | H38: 2400
B39: PLATE | C39: pl.rinn | D39: SM490 | E39: 120 | F39: CIRC | G39: mc | H39: 1900
B40: PLATE | C40: pl.dk | D40: SM490 | E40: 30 | F40: RECT | G40: mc | H40: 3800 | I40: 2600
B41: PLATE | C41: pl.gbx | D41: SM490 | E41: 350 | F41: RECT | G41: mc | H41: 650 | I41: 500
B42: PLATE | C42: pl.hcap | D42: SM490 | E42: 40 | F42: RECT | G42: mc | H42: 900 | I42: 900
...
