Workbook

Sheet PARAM
B1: COLUMN NODE
B2: One column, four beams, and up to two splices. Fill in the blue cells — the input tab is written from this one.
B4: 1. COLUMN | C4: an H or a square tube - fill in the row that matches Type, the other is ignored
C5: Section | D5: h | E5: b | F5: tw / t | G5: tf | H5: r | I5: kg/m
B6: H section | C6: H-300x300x10x15 r18 | D6: =IFERROR(VLOOKUP($C$6,SECT!$A:$G,2,FALSE),"") -> 300 | E6: =IFERROR(VLOOKUP($C$6,SECT!$A:$G,3,FALSE),"") -> 300 | F6: =IFERROR(VLOOKUP($C$6,SECT!$A:$G,4,FALSE),"") -> 10 | G6: =IFERROR(VLOOKUP($C$6,SECT!$A:$G,5,FALSE),"") -> 15 | H6: =IFERROR(VLOOKUP($C$6,SECT!$A:$G,6,FALSE),"") -> 18 | I6: =IFERROR(VLOOKUP($C$6,SECT!$A:$G,7,FALSE),"") -> 94
B7: Square tube | D7: 300 | E7: 300 | F7: 12 | G7: 24 | H7: r blank = square corner
B8: Type | C8: middle | D8: upper | E8: lower | G8: Steel
B9: Lengths | C9: 1400 | D9: 700 | E9: 700 | G9: SS275
B10: Upper and lower are the column above and below the splice. Type 0 and that splice is gone — the piece, its two plates and its four bolts.
B11: checked for you | C11: face X | D11: =IF(PARAM!$C$8="H",PARAM!$D$6/2,PARAM!$D$7/2) -> 150 | E11: face Y | F11: =IF(PARAM!$C$8="H",PARAM!$F$6/2,PARAM!$E$7/2) -> 5 | G11: splices | H11: =(IF(PARAM!$D$9>0,1,0)+IF(PARAM!$E$9>0,1,0))&" of 2" -> 2 of 2
B13: 2. BEAMS | C13: one section, four faces - each face takes an end plate, a fin plate, or nothing
C14: Section | D14: h | E14: b | F14: tw | G14: tf | H14: r | I14: kg/m | J14: Length
B15: Beam | C15: H-300x150x6.5x9 r13 | D15: =IFERROR(VLOOKUP($C$15,SECT!$A:$G,2,FALSE),"") -> 300 | E15: =IFERROR(VLOOKUP($C$15,SECT!$A:$G,3,FALSE),"") -> 150 | F15: =IFERROR(VLOOKUP($C$15,SECT!$A:$G,4,FALSE),"") -> 6.5 | G15: =IFERROR(VLOOKUP($C$15,SECT!$A:$G,5,FALSE),"") -> 9 | H15: =IFERROR(VLOOKUP($C$15,SECT!$A:$G,6,FALSE),"") -> 13 | I15: =IFERROR(VLOOKUP($C$15,SECT!$A:$G,7,FALSE),"") -> 36.7 | J15: 900
C16: +X flange face | E16: -X flange face | G16: +Y web face | I16: -Y web face
B17: Connection | C17: end plate | E17: fin plate | G17: fin plate | I17: end plate
B18: On an H column the X faces are the flanges and the Y faces are the web, so a Y beam sits between the flanges. A tube has four alike walls.
B19: checked for you | C19: between flanges | D19: =IF(PARAM!$C$8<>"H","n/a - tube",IF(PARAM!$E$15<=PARAM!$D$6-2*PARAM!$G$6,PARAM!$E$15&" ≤ "&(PARAM!$D$6-2*PARAM!$G$6),"beam too wide")) -> 150 ≤ 270 | E19: connectors | F19: =COUNTIF(PARAM!$C$17&PARAM!$E$17&PARAM!$G$17&PARAM!$I$17,"*")&" faces set" -> 4 faces set | G19: end plate on a tube | H19: =IF(AND(PARAM!$C$8="R",OR(PARAM!$C$17="end plate",PARAM!$E$17="end plate",PARAM!$G$17="end plate",PARAM!$I$17="end plate")),"needs blind bolts","-") -> -
B21: 3. CONNECTORS | C21: height follows the bolts, so a plate can never be shorter than the chain it carries
C22: width / reach | D22: height | E22: thickness | F22: gauge | G22: overhang | H22: edge
B23: End plate | C23: 180 | D23: =PARAM!$F$31*(PARAM!$G$31-1)+2*PARAM!$G$23 -> 230 | E23: 12 | F23: 90 | H23: 45
B24: Fin plate | C24: 140 | D24: =PARAM!$F$31*(PARAM!$G$31-1)+2*PARAM!$G$23 -> 230 | E24: 10 | F24: 60
B25: Splice plate | C25: =IF(PARAM!$C$8="H",PARAM!$D$6,PARAM!$D$7)+2*PARAM!$F$25 -> 420 | D25: =IF(PARAM!$C$8="H",PARAM!$E$6,PARAM!$E$7)+2*PARAM!$F$25 -> 420 | E25: 20 | F25: 60
B26: End plate gauge is across the beam web; fin plate gauge is out from the column face. The splice plate is the column plus an overhang all round.
B27: checked for you | C27: ep clears web | D27: =IF(PARAM!$F$23/2>=PARAM!$F$15/2+1.5*PARAM!$D$31,"ok","gauge too tight") -> ok | E27: ep width | F27: =IF(PARAM!$C$23>=PARAM!$F$23+3*PARAM!$D$31,PARAM!$C$23&" ≥ "&(PARAM!$F$23+3*PARAM!$D$31),"too narrow") -> 180 ≥ 138 | G27: fin reach | H27: =IF(PARAM!$C$24>=PARAM!$F$24+1.5*PARAM!$D$31,PARAM!$C$24&" ≥ "&(PARAM!$F$24+1.5*PARAM!$D$31),"too short") -> 140 ≥ 84 | I27: edge | J27: =IF(PARAM!$G$23>=1.5*PARAM!$D$31,PARAM!$G$23&" ≥ "&(1.5*PARAM!$D$31),"under 1.5d") -> 45 ≥ 24
B29: 4. BOLTS | C29: one size throughout; two lengths, because a splice grips two plates and a connection grips one
C30: Grade | D30: Dia | E30: Hole | F30: Pitch | G30: Count
B31: Bolt | C31: F10T | D31: 16 | E31: =PARAM!$D$31+2 -> 18 | F31: 70 | G31: 3
C32: grip end plate | D32: grip fin | E32: grip splice | F32: nut | G32: LENGTH conn | H32: LENGTH splice
B33: Lengths | C33: =IF(PARAM!$C$8="H",PARAM!$G$6,PARAM!$F$7)+PARAM!$E$23 -> 27 | D33: =PARAM!$E$24+PARAM!$F$15 -> 16.5 | E33: =2*PARAM!$E$25 -> 40 | F33: =0.9*PARAM!$D$31 -> 14.4 | G33: =CEILING(MAX(PARAM!$C$33,PARAM!$D$33,IF(PARAM!$C$8="H",PARAM!$F$6,PARAM!$F$7)+PARAM!$E$23)+PARAM!$F$33+0.2*PARAM!$D$31,5) -> 45 | H33: =CEILING(PARAM!$E$33+PARAM!$F$33+0.2*PARAM!$D$31,5) -> 60
B34: proj — the thread past the nut — takes up what each grip leaves, so every connection bolt is one take-off line and every splice bolt another.
B35: checked for you | C35: pitch | D35: =IF(PARAM!$F$31>=2.5*PARAM!$D$31,PARAM!$F$31&" ≥ "&(2.5*PARAM!$D$31),"under 2.5d") -> 70 ≥ 40 | E35: conn bolt | F35: =PARAM!$G$33&" for "&ROUND(MAX(PARAM!$C$33,PARAM!$D$33),1) -> 45 for 27 | G35: splice bolt | H35: =PARAM!$H$33&" for "&PARAM!$E$33 -> 60 for 40

Sheet input
A1: Written from PARAM. Nothing here needs editing — change the front sheet instead.
A2: There is no CUT row in this file. BOLT drills what its shank passes through, plates included, so a hole is never drawn twice.
B3: COORD | C3: ZUP
A5: SECT id material length TYPE base.pt v1..v7 an H wants seven values, a tube wants four - the last three go blank by formula
A6: the column: middle, upper, lower. MAX(1,..) keeps a definition alive even when its piece is switched off above | B6: SECT | C6: sc.c1 | D6: =PARAM!$G$9 -> SS275 | E6: =PARAM!$C$9 -> 1400 | F6: =IF(PARAM!$C$8="H","H","R") -> H | G6: mc | H6: =IF(PARAM!$C$8="H",PARAM!$D$6,PARAM!$D$7) -> 300 | I6: =IF(PARAM!$C$8="H",PARAM!$E$6,PARAM!$E$7) -> 300 | J6: =IF(PARAM!$C$8="H",PARAM!$E$6,PARAM!$F$7) -> 300 | K6: =IF(PARAM!$C$8="H",PARAM!$F$6,PARAM!$G$7) -> 10 | L6: =IF(PARAM!$C$8="H",PARAM!$G$6,"") -> 15 | M6: =IF(PARAM!$C$8="H",PARAM!$G$6,"") -> 15 | N6: =IF(PARAM!$C$8="H",PARAM!$H$6,"") -> 18
B7: SECT | C7: sc.c2 | D7: =PARAM!$G$9 -> SS275 | E7: =MAX(1,PARAM!$D$9) -> 700 | F7: =IF(PARAM!$C$8="H","H","R") -> H | G7: mc | H7: =IF(PARAM!$C$8="H",PARAM!$D$6,PARAM!$D$7) -> 300 | I7: =IF(PARAM!$C$8="H",PARAM!$E$6,PARAM!$E$7) -> 300 | J7: =IF(PARAM!$C$8="H",PARAM!$E$6,PARAM!$F$7) -> 300 | K7: =IF(PARAM!$C$8="H",PARAM!$F$6,PARAM!$G$7) -> 10 | L7: =IF(PARAM!$C$8="H",PARAM!$G$6,"") -> 15 | M7: =IF(PARAM!$C$8="H",PARAM!$G$6,"") -> 15 | N7: =IF(PARAM!$C$8="H",PARAM!$H$6,"") -> 18
B8: SECT | C8: sc.c3 | D8: =PARAM!$G$9 -> SS275 | E8: =MAX(1,PARAM!$E$9) -> 700 | F8: =IF(PARAM!$C$8="H","H","R") -> H | G8: mc | H8: =IF(PARAM!$C$8="H",PARAM!$D$6,PARAM!$D$7) -> 300 | I8: =IF(PARAM!$C$8="H",PARAM!$E$6,PARAM!$E$7) -> 300 | J8: =IF(PARAM!$C$8="H",PARAM!$E$6,PARAM!$F$7) -> 300 | K8: =IF(PARAM!$C$8="H",PARAM!$F$6,PARAM!$G$7) -> 10 | L8: =IF(PARAM!$C$8="H",PARAM!$G$6,"") -> 15 | M8: =IF(PARAM!$C$8="H",PARAM!$G$6,"") -> 15 | N8: =IF(PARAM!$C$8="H",PARAM!$H$6,"") -> 18
A9: the beam, one section for all four arms | B9: SECT | C9: sc.bm | D9: =PARAM!$G$9 -> SS275 | E9: =PARAM!$J$15 -> 900 | F9: H | G9: mc | H9: =PARAM!$D$15 -> 300 | I9: =PARAM!$E$15 -> 150 | J9: =PARAM!$E$15 -> 150 | K9: =PARAM!$F$15 -> 6.5 | L9: =PARAM!$G$15 -> 9 | M9: =PARAM!$G$15 -> 9 | N9: =PARAM!$H$15 -> 13
A11: PLATE id material thickness RECT base.pt B H
A12: end plate - welded to the beam, bolted to the column | B12: PLATE | C12: pl.ep | D12: =PARAM!$G$9 -> SS275 | E12: =PARAM!$E$23 -> 12 | F12: RECT | G12: mc | H12: =PARAM!$C$23 -> 180 | I12: =PARAM!$D$23 -> 230
A13: fin plate - welded to the column, bolted through the beam web | B13: PLATE | C13: pl.fin | D13: =PARAM!$G$9 -> SS275 | E13: =PARAM!$E$24 -> 10 | F13: RECT | G13: mc | H13: =PARAM!$C$24 -> 140 | I13: =PARAM!$D$24 -> 230
A14: splice plate - the column plus an overhang all round | B14: PLATE | C14: pl.sp | D14: =PARAM!$G$9 -> SS275 | E14: =PARAM!$E$25 -> 20 | F14: RECT | G14: mc | H14: =PARAM!$C$25 -> 420 | I14: =PARAM!$D$25 -> 420
A16: BOLT id material dia length hole [head_af] [head_h] [nut_af] nut_h proj
A17: end plate bolt | B17: BOLT | C17: bo.ep | D17: =PARAM!$C$31 -> F10T | E17: =PARAM!$D$31 -> 16 | F17: =PARAM!$G$33 -> 45 | G17: =PARAM!$E$31 -> 18 | K17: =PARAM!$F$33 -> 14.4 | L17: =PARAM!$G$33-PARAM!$C$33-PARAM!$F$33 -> 3.6
A18: fin plate bolt - same length, more thread showing | B18: BOLT | C18: bo.fin | D18: =PARAM!$C$31 -> F10T | E18: =PARAM!$D$31 -> 16 | F18: =PARAM!$G$33 -> 45 | G18: =PARAM!$E$31 -> 18 | K18: =PARAM!$F$33 -> 14.4 | L18: =PARAM!$G$33-PARAM!$D$33-PARAM!$F$33 -> 14.1
A19: splice bolt | B19: BOLT | C19: bo.sp | D19: =PARAM!$C$31 -> F10T | E19: =PARAM!$D$31 -> 16 | F19: =PARAM!$H$33 -> 60 | G19: =PARAM!$E$31 -> 18 | K19: =PARAM!$F$33 -> 14.4 | L19: =PARAM!$H$33-PARAM!$E$33-PARAM!$F$33 -> 5.6
A21: MODULE id member Ref.Pt L.X L.Y L.Z PLANE [ROT.X ROT.Y ROT.Z] [dx dy dz repeat]
A22: ROT.Z 90 turns the column so its h runs along X. A square column cannot show that in a bounding box, so it is written down rather than looked for.
A23: a blank member is simply not there - which is how a length of 0 removes a piece | B23: MODULE | C23: md.c1 | D23: ="sc.c1" -> sc.c1 | F23: 0 | G23: 0 | H23: 0 | I23: XY | J23: 0 | K23: 0 | L23: 90
B24: MODULE | C24: md.c1 | D24: BASE | E24: sc.c1 | F24: mc
B25: MODULE | C25: md.c2 | D25: =IF(PARAM!$D$9>0,"sc.c2","") -> sc.c2 | F25: 0 | G25: 0 | H25: 0 | I25: XY | J25: 0 | K25: 0 | L25: 90
B26: MODULE | C26: md.c2 | D26: BASE | E26: sc.c2 | F26: mc
B27: MODULE | C27: md.c3 | D27: =IF(PARAM!$E$9>0,"sc.c3","") -> sc.c3 | F27: 0 | G27: 0 | H27: 0 | I27: XY | J27: 0 | K27: 0 | L27: 90
B28: MODULE | C28: md.c3 | D28: BASE | E28: sc.c3 | F28: mc
A30: arm ax - the +X face, "end plate" on PARAM. Both details are written out and PARAM keeps one.
A31: end plate - welded to the beam end, bearing on the column | B31: MODULE | C31: md.ax | D31: =IF(PARAM!$C$17="end plate","pl.ep","") -> pl.ep | E31: mc | F31: =-PARAM!$E$23/2 -> -6 | G31: =0 -> 0 | H31: 0 | I31: YZ | J31: 0 | K31: 0 | L31: 0
A32: fin plate - welded to the column, standing beside the beam web | B32: MODULE | C32: md.ax | D32: =IF(PARAM!$C$17="fin plate","pl.fin","") | E32: mc | F32: =PARAM!$C$24/2 -> 70 | G32: =8.25 -> 8.25 | H32: 0 | I32: XZ | J32: 0 | K32: 0 | L32: 0
A33: the beam - at the module origin, and the one member always there | B33: MODULE | C33: md.ax | D33: sc.bm | F33: 0 | G33: 0 | H33: 0 | I33: YZ | J33: 0 | K33: 0 | L33: 0
A34: an end plate bolt runs along the beam, a fin plate bolt across it | B34: MODULE | C34: md.ax | D34: =IF(PARAM!$C$17="end plate","bo.ep",IF(PARAM!$C$17="fin plate","bo.fin","")) -> bo.ep | F34: =IF(PARAM!$C$17="end plate",-(IF(PARAM!$C$8="H",PARAM!$G$6,PARAM!$F$7)+PARAM!$E$23),PARAM!$F$24) -> -27 | G34: =IF(PARAM!$C$17="end plate",PARAM!$F$23/2,PARAM!$F$15/2+PARAM!$E$24) -> 45 | H34: =-PARAM!$F$31*(PARAM!$G$31-1)/2 -> -70 | I34: =IF(PARAM!$C$17="end plate","YZ","XZ") -> YZ | J34: 0 | K34: 0 | L34: 0 | M34: =IF(PARAM!$C$17="end plate",0,0) -> 0 | N34: =IF(PARAM!$C$17="end plate",-PARAM!$F$23,0) -> -90 | O34: 0 | P34: =IF(PARAM!$C$17="end plate",1,0) -> 1 | Q34: 0 | R34: 0 | S34: =PARAM!$F$31 -> 70 | T34: =PARAM!$G$31-1 -> 2
B35: MODULE | C35: md.ax | D35: BASE | E35: sc.bm | F35: mc
A37: arm bx - the -X face, "fin plate" on PARAM. Both details are written out and PARAM keeps one.
A38: end plate - welded to the beam end, bearing on the column | B38: MODULE | C38: md.bx | D38: =IF(PARAM!$E$17="end plate","pl.ep","") | E38: mc | F38: =-(-PARAM!$E$23/2) -> 6 | G38: =0 -> 0 | H38: 0 | I38: YZ | J38: 0 | K38: 0 | L38: 180
A39: fin plate - welded to the column, standing beside the beam web | B39: MODULE | C39: md.bx | D39: =IF(PARAM!$E$17="fin plate","pl.fin","") -> pl.fin | E39: mc | F39: =-(PARAM!$C$24/2) -> -70 | G39: =8.25 -> 8.25 | H39: 0 | I39: XZ | J39: 0 | K39: 0 | L39: 180
A40: the beam - at the module origin, and the one member always there | B40: MODULE | C40: md.bx | D40: sc.bm | F40: 0 | G40: 0 | H40: 0 | I40: YZ | J40: 0 | K40: 0 | L40: 180
A41: an end plate bolt runs along the beam, a fin plate bolt across it | B41: MODULE | C41: md.bx | D41: =IF(PARAM!$E$17="end plate","bo.ep",IF(PARAM!$E$17="fin plate","bo.fin","")) -> bo.fin | F41: =-(IF(PARAM!$E$17="end plate",-(IF(PARAM!$C$8="H",PARAM!$G$6,PARAM!$F$7)+PARAM!$E$23),PARAM!$F$24)) -> -60 | G41: =IF(PARAM!$E$17="end plate",PARAM!$F$23/2,PARAM!$F$15/2+PARAM!$E$24) -> 13.25 | H41: =-PARAM!$F$31*(PARAM!$G$31-1)/2 -> -70 | I41: =IF(PARAM!$E$17="end plate","YZ","XZ") -> XZ | J41: 0 | K41: 0 | L41: 180 | M41: =IF(PARAM!$E$17="end plate",0,0) -> 0 | N41: =IF(PARAM!$E$17="end plate",-PARAM!$F$23,0) -> 0 | O41: 0 | P41: =IF(PARAM!$E$17="end plate",1,0) -> 0 | Q41: 0 | R41: 0 | S41: =PARAM!$F$31 -> 70 | T41: =PARAM!$G$31-1 -> 2
B42: MODULE | C42: md.bx | D42: BASE | E42: sc.bm | F42: mc
A44: arm ay - the +Y face, "fin plate" on PARAM. Both details are written out and PARAM keeps one.
A45: end plate - welded to the beam end, bearing on the column | B45: MODULE | C45: md.ay | D45: =IF(PARAM!$G$17="end plate","pl.ep","") | E45: mc | F45: =0 -> 0 | G45: =-PARAM!$E$23/2 -> -6 | H45: 0 | I45: XZ | J45: 0 | K45: 0 | L45: 180
A46: fin plate - welded to the column, standing beside the beam web | B46: MODULE | C46: md.ay | D46: =IF(PARAM!$G$17="fin plate","pl.fin","") -> pl.fin | E46: mc | F46: =8.25 -> 8.25 | G46: =PARAM!$C$24/2 -> 70 | H46: 0 | I46: YZ | J46: 0 | K46: 0 | L46: 180
A47: the beam - at the module origin, and the one member always there | B47: MODULE | C47: md.ay | D47: sc.bm | F47: 0 | G47: 0 | H47: 0 | I47: XZ | J47: 0 | K47: 0 | L47: 180
...

Sheet SECT
A1: Section | B1: h | C1: b | D1: tw | E1: tf | F1: r | G1: kg/m
A2: H-100x100x6x8 r10 | B2: 100 | C2: 100 | D2: 6 | E2: 8 | F2: 10 | G2: 17.2
A3: H-125x125x6.5x9 r10 | B3: 125 | C3: 125 | D3: 6.5 | E3: 9 | F3: 10 | G3: 23.8
A4: H-150x75x5x7 r8 | B4: 150 | C4: 75 | D4: 5 | E4: 7 | F4: 8 | G4: 14
A5: H-148x100x6x9 r11 | B5: 148 | C5: 100 | D5: 6 | E5: 9 | F5: 11 | G5: 21.1
A6: H-150x150x7x10 r11 | B6: 150 | C6: 150 | D6: 7 | E6: 10 | F6: 11 | G6: 31.5
A7: H-198x99x4.5x7 r11 | B7: 198 | C7: 99 | D7: 4.5 | E7: 7 | F7: 11 | G7: 18.2
A8: H-200x100x5.5x8 r11 | B8: 200 | C8: 100 | D8: 5.5 | E8: 8 | F8: 11 | G8: 21.3
A9: H-194x150x6x9 r13 | B9: 194 | C9: 150 | D9: 6 | E9: 9 | F9: 13 | G9: 30.6
A10: H-200x200x8x12 r13 | B10: 200 | C10: 200 | D10: 8 | E10: 12 | F10: 13 | G10: 49.9
A11: H-200x204x12x12 r13 | B11: 200 | C11: 204 | D11: 12 | E11: 12 | F11: 13 | G11: 56.2
A12: H-248x124x5x8 r12 | B12: 248 | C12: 124 | D12: 5 | E12: 8 | F12: 12 | G12: 25.7
A13: H-250x125x6x9 r12 | B13: 250 | C13: 125 | D13: 6 | E13: 9 | F13: 12 | G13: 29.6
... A59: H-918x303x19x37 r18 | B59: 918 | C59: 303 | D59: 19 | E59: 37 | F59: 18 | G59: 304
