Workbook

Sheet SECT
A1: Section | B1: H | C1: B | D1: t1 | E1: t2 | F1: r | G1: kg/m
A2: H-100x100x6x8 r10 | B2: 100 | C2: 100 | D2: 6 | E2: 8 | F2: 10 | G2: 17.2
A3: H-125x125x6.5x9 r10 | B3: 125 | C3: 125 | D3: 6.5 | E3: 9 | F3: 10 | G3: 23.8
A4: H-150x75x5x7 r8 | B4: 150 | C4: 75 | D4: 5 | E4: 7 | F4: 8 | G4: 14
A5: H-148x100x6x9 r11 | B5: 148 | C5: 100 | D5: 6 | E5: 9 | F5: 11 | G5: 21.1
A6: H-150x150x7x10 r11 | B6: 150 | C6: 150 | D6: 7 | E6: 10 | F6: 11 | G6: 31.5
A7: H-198x99x4.5x7 r11 | B7: 198 | C7: 99 | D7: 4.5 | E7: 7 | F7: 11 | G7: 18.2
A8: H-200x100x5.5x8 r11 | B8: 200 | C8: 100 | D8: 5.5 | E8: 8 | F8: 11 | G8: 21.3
A9: H-194x150x6x9 r13 | B9: 194 | C9: 150 | D9: 6 | E9: 9 | F9: 13 | G9: 30.6
A10: H-200x200x8x12 r13 | B10: 200 | C10: 200 | D10: 8 | E10: 12 | F10: 13 | G10: 49.9
A11: H-200x204x12x12 r13 | B11: 200 | C11: 204 | D11: 12 | E11: 12 | F11: 13 | G11: 56.2
A12: H-248x124x5x8 r12 | B12: 248 | C12: 124 | D12: 5 | E12: 8 | F12: 12 | G12: 25.7
A13: H-250x125x6x9 r12 | B13: 250 | C13: 125 | D13: 6 | E13: 9 | F13: 12 | G13: 29.6
... A59: H-918x303x19x37 r18 | B59: 918 | C59: 303 | D59: 19 | E59: 37 | F59: 18 | G59: 304

Sheet PARAM
B1: BOLTED SPLICE
B2: Fill in the blue cells. Everything else follows — the input tab is written from this one, and nothing on it needs touching.
B4: 1. MEMBER AND JOINT | C4: pick a section and the sizes fill themselves in
C5: Section | D5: H | E5: B | F5: t1 web | G5: t2 flange | H5: r | I5: kg/m | J5: Length
B6: Member | C6: H-300x300x10x15 r18 | D6: =IFERROR(VLOOKUP($C$6,SECT!$A:$G,2,FALSE),"") -> 300 | E6: =IFERROR(VLOOKUP($C$6,SECT!$A:$G,3,FALSE),"") -> 300 | F6: =IFERROR(VLOOKUP($C$6,SECT!$A:$G,4,FALSE),"") -> 10 | G6: =IFERROR(VLOOKUP($C$6,SECT!$A:$G,5,FALSE),"") -> 15 | H6: =IFERROR(VLOOKUP($C$6,SECT!$A:$G,6,FALSE),"") -> 18 | I6: =IFERROR(VLOOKUP($C$6,SECT!$A:$G,7,FALSE),"") -> 94 | J6: 1800
B7: Joint gap | C7: 20
B8: One section, spliced to itself — both sides of the joint are the same member, so there is one row to fill in and Length is the reach of each side. Each side is drawn as three plates — top flange, bottom flange, web — because a rolled section cannot be drilled: a CUT on a SECT cuts its whole length. Root fillets are modelled as eight fillet strips.
B10: checked for you | C10: clear web depth | D10: ==PARAM!$D$6-2*PARAM!$G$6 -> 270 | E10: member centre at ± | F10: ==PARAM!$C$7/2+PARAM!$J$6/2 -> 910
B12: 2. SPLICE PLATES | C12: width across, length along the beam
C13: Width | D13: Length | E13: Thick | F13: Qty | G13: Material
B14: Top plate | C14: 280 | D14: 300 | E14: 12 | F14: 1 | G14: SM355
B15: Top inner plate | C15: 110 | D15: 300 | E15: 10 | F15: 2 | G15: SM355
B16: Web plate | C16: 220 | D16: 280 | E16: 10 | F16: 2 | G16: SM355
B17: Bottom inner plate | C17: 110 | D17: 300 | E17: 10 | F17: 2 | G17: SM355
B18: Bottom plate | C18: 280 | D18: 300 | E18: 12 | F18: 1 | G18: SM355
B20: checked for you | C20: plate steel, kg | D20: ==ROUND((PARAM!$C$14*PARAM!$D$14*PARAM!$E$14*2+PARAM!$C$15*PARAM!$D$15*PARAM!$E$15*4+PARAM!$C$16*PARAM!$D$16*PARAM!$E$16*2)*7.85/1000000,1) -> 35.9
B22: 3. BOLTS | C22: the shank and the hole are different sizes
C23: Bolt dia | D23: Hole dia | E23: Grade | F23: Flange bolt L | G23: Web bolt L
B24: Bolt | C24: 22 | D24: 24 | E24: F10T | F24: =PARAM!$E$14+PARAM!$G$6+PARAM!$E$15+30 -> 67 | G24: =PARAM!$F$6+2*PARAM!$E$16+30 -> 60
B26: bolt group | C26: Long N | D26: In | E26: Out | F26: Trans N | G26: In | H26: Out
B27: Top flange | C27: 4 | D27: 70 | E27: 40 | F27: 4 | G27: 100 | H27: 35
B28: Web | C28: 4 | D28: 60 | E28: 40 | F28: 3 | G28: 0 | H28: 40
B29: Bottom flange | C29: 4 | D29: 70 | E29: 40 | F29: 4 | G29: 100 | H29: 35
B30: Long = along the beam, Trans = across the flange or through the web depth. In is the gap left in the middle, Out the edge distance. The web opens with Trans In = 0: its bolts run right through the depth with no gap at the neutral axis.
B31: checked for you | C31: flange pitch | D31: ==ROUND((PARAM!$D$14/2-PARAM!$E$27-PARAM!$D$27/2)/(PARAM!$C$27/2-1),1)&" / "&ROUND((PARAM!$C$14/2-PARAM!$H$27-PARAM!$G$27/2)/(PARAM!$F$27/2-1),1) -> 75 / 55 | E31: web pitch | F31: ==ROUND((PARAM!$D$16/2-PARAM!$E$28-PARAM!$D$28/2)/(PARAM!$C$28/2-1),1)&" / "&ROUND((PARAM!$C$16-2*PARAM!$H$28-PARAM!$G$28)/(PARAM!$F$28-1),1) -> 70 / 70 | G31: bolts | H31: ==PARAM!$C$27*PARAM!$F$27+PARAM!$C$29*PARAM!$F$29+PARAM!$C$28*PARAM!$F$28 -> 44
B34: 4. WHAT THE NUMBERS MEAN | C34: the same drawings, to the sizes above
B36: The joint in plan — one section either side, and the gap between
B61: The section at the joint — which plate goes where
B92: Top flange and Bottom flange bolt groups
B131: Web bolt group — Trans In is 0, so the depth is one run

Sheet input
A1: Written from PARAM. Nothing here needs editing — change the front sheet instead.
B2: COORD | C2: ZUP
A4: the bolt hole - PARAM row 24, the hole column, not the shank | B4: HOLE | C4: ho.b | D4: CIRC | E4: mc | F4: ==PARAM!$D$24 -> 24
A5: the root fillet: a disc of 2r taken out of an r x r square leaves the concave corner | B5: HOLE | C5: ho.fil | D5: CIRC | E5: mc | F5: ==2*PARAM!$H$6 -> 36
A7: PLATE id material thickness RECT base.pt B(along beam) H(across)
A8: beam top flange, one member | B8: PLATE | C8: pl.tf | D8: ==PARAM!$G$14 -> SM355 | E8: ==PARAM!$G$6 -> 15 | F8: RECT | G8: mc | H8: ==PARAM!$J$6 -> 1800 | I8: ==PARAM!$E$6 -> 300
A9: beam bottom flange | B9: PLATE | C9: pl.bf | D9: ==PARAM!$G$14 -> SM355 | E9: ==PARAM!$G$6 -> 15 | F9: RECT | G9: mc | H9: ==PARAM!$J$6 -> 1800 | I9: ==PARAM!$E$6 -> 300
A10: beam web | B10: PLATE | C10: pl.wb | D10: ==PARAM!$G$14 -> SM355 | E10: ==PARAM!$F$6 -> 10 | F10: RECT | G10: mc | H10: ==PARAM!$J$6 -> 1800 | I10: ==PARAM!$D$6-2*PARAM!$G$6 -> 270
A11: root fillet, x8 - four each member | B11: PLATE | C11: pl.fil | D11: ==PARAM!$G$14 -> SM355 | E11: ==PARAM!$J$6 -> 1800 | F11: RECT | G11: mc | H11: ==PARAM!$H$6 -> 18 | I11: ==PARAM!$H$6 -> 18
A12: outer top plate | B12: PLATE | C12: pl.tp | D12: ==PARAM!$G$14 -> SM355 | E12: ==PARAM!$E$14 -> 12 | F12: RECT | G12: mc | H12: ==PARAM!$D$14 -> 300 | I12: ==PARAM!$C$14 -> 280
A13: inner top plate, x2 | B13: PLATE | C13: pl.ti | D13: ==PARAM!$G$15 -> SM355 | E13: ==PARAM!$E$15 -> 10 | F13: RECT | G13: mc | H13: ==PARAM!$D$15 -> 300 | I13: ==PARAM!$C$15 -> 110
A14: web plate, x2 | B14: PLATE | C14: pl.wp | D14: ==PARAM!$G$16 -> SM355 | E14: ==PARAM!$E$16 -> 10 | F14: RECT | G14: mc | H14: ==PARAM!$D$16 -> 280 | I14: ==PARAM!$C$16 -> 220
A15: inner bottom plate, x2 | B15: PLATE | C15: pl.bi | D15: ==PARAM!$G$17 -> SM355 | E15: ==PARAM!$E$17 -> 10 | F15: RECT | G15: mc | H15: ==PARAM!$D$17 -> 300 | I15: ==PARAM!$C$17 -> 110
A16: outer bottom plate | B16: PLATE | C16: pl.bp | D16: ==PARAM!$G$18 -> SM355 | E16: ==PARAM!$E$18 -> 12 | F16: RECT | G16: mc | H16: ==PARAM!$D$18 -> 300 | I16: ==PARAM!$C$18 -> 280
A18: BAR id material diameter length the shank, not the hole
A19: flange bolt - length from PARAM, which you can overwrite | B19: BAR | C19: bo.f | D19: SS275 | E19: ==PARAM!$C$24 -> 22 | F19: ==PARAM!$F$24 -> 67
A20: web bolt | B20: BAR | C20: bo.w | D20: SS275 | E20: ==PARAM!$C$24 -> 22 | F20: ==PARAM!$G$24 -> 60
A22: CUT plate L.X L.Y shape dx dy repeat dx2 dy2 repeat2 one row per quadrant the plate reaches
A23: outer top plate - four quadrants | B23: CUT | C23: pl.tp | D23: ==(PARAM!$D$27/2) -> 35 | E23: ==(PARAM!$G$27/2) -> 50 | F23: ho.b | G23: ==((PARAM!$D$14/2-PARAM!$E$27-PARAM!$D$27/2)/(PARAM!$C$27/2-1)) -> 75 | H23: 0 | I23: ==PARAM!$C$27/2-1 -> 1 | J23: 0 | K23: ==((PARAM!$C$14/2-PARAM!$H$27-PARAM!$G$27/2)/(PARAM!$F$27/2-1)) -> 55 | L23: ==PARAM!$F$27/2-1 -> 1
B24: CUT | C24: pl.tp | D24: ==(PARAM!$D$27/2) -> 35 | E24: ==-(PARAM!$G$27/2) -> -50 | F24: ho.b | G24: ==((PARAM!$D$14/2-PARAM!$E$27-PARAM!$D$27/2)/(PARAM!$C$27/2-1)) -> 75 | H24: 0 | I24: ==PARAM!$C$27/2-1 -> 1 | J24: 0 | K24: ==-((PARAM!$C$14/2-PARAM!$H$27-PARAM!$G$27/2)/(PARAM!$F$27/2-1)) -> -55 | L24: ==PARAM!$F$27/2-1 -> 1
B25: CUT | C25: pl.tp | D25: ==-(PARAM!$D$27/2) -> -35 | E25: ==(PARAM!$G$27/2) -> 50 | F25: ho.b | G25: ==-((PARAM!$D$14/2-PARAM!$E$27-PARAM!$D$27/2)/(PARAM!$C$27/2-1)) -> -75 | H25: 0 | I25: ==PARAM!$C$27/2-1 -> 1 | J25: 0 | K25: ==((PARAM!$C$14/2-PARAM!$H$27-PARAM!$G$27/2)/(PARAM!$F$27/2-1)) -> 55 | L25: ==PARAM!$F$27/2-1 -> 1
B26: CUT | C26: pl.tp | D26: ==-(PARAM!$D$27/2) -> -35 | E26: ==-(PARAM!$G$27/2) -> -50 | F26: ho.b | G26: ==-((PARAM!$D$14/2-PARAM!$E$27-PARAM!$D$27/2)/(PARAM!$C$27/2-1)) -> -75 | H26: 0 | I26: ==PARAM!$C$27/2-1 -> 1 | J26: 0 | K26: ==-((PARAM!$C$14/2-PARAM!$H$27-PARAM!$G$27/2)/(PARAM!$F$27/2-1)) -> -55 | L26: ==PARAM!$F$27/2-1 -> 1
A27: outer bottom plate - four quadrants | B27: CUT | C27: pl.bp | D27: ==(PARAM!$D$27/2) -> 35 | E27: ==(PARAM!$G$27/2) -> 50 | F27: ho.b | G27: ==((PARAM!$D$14/2-PARAM!$E$27-PARAM!$D$27/2)/(PARAM!$C$27/2-1)) -> 75 | H27: 0 | I27: ==PARAM!$C$27/2-1 -> 1 | J27: 0 | K27: ==((PARAM!$C$14/2-PARAM!$H$27-PARAM!$G$27/2)/(PARAM!$F$27/2-1)) -> 55 | L27: ==PARAM!$F$27/2-1 -> 1
B28: CUT | C28: pl.bp | D28: ==(PARAM!$D$27/2) -> 35 | E28: ==-(PARAM!$G$27/2) -> -50 | F28: ho.b | G28: ==((PARAM!$D$14/2-PARAM!$E$27-PARAM!$D$27/2)/(PARAM!$C$27/2-1)) -> 75 | H28: 0 | I28: ==PARAM!$C$27/2-1 -> 1 | J28: 0 | K28: ==-((PARAM!$C$14/2-PARAM!$H$27-PARAM!$G$27/2)/(PARAM!$F$27/2-1)) -> -55 | L28: ==PARAM!$F$27/2-1 -> 1
B29: CUT | C29: pl.bp | D29: ==-(PARAM!$D$27/2) -> -35 | E29: ==(PARAM!$G$27/2) -> 50 | F29: ho.b | G29: ==-((PARAM!$D$14/2-PARAM!$E$27-PARAM!$D$27/2)/(PARAM!$C$27/2-1)) -> -75 | H29: 0 | I29: ==PARAM!$C$27/2-1 -> 1 | J29: 0 | K29: ==((PARAM!$C$14/2-PARAM!$H$27-PARAM!$G$27/2)/(PARAM!$F$27/2-1)) -> 55 | L29: ==PARAM!$F$27/2-1 -> 1
B30: CUT | C30: pl.bp | D30: ==-(PARAM!$D$27/2) -> -35 | E30: ==-(PARAM!$G$27/2) -> -50 | F30: ho.b | G30: ==-((PARAM!$D$14/2-PARAM!$E$27-PARAM!$D$27/2)/(PARAM!$C$27/2-1)) -> -75 | H30: 0 | I30: ==PARAM!$C$27/2-1 -> 1 | J30: 0 | K30: ==-((PARAM!$C$14/2-PARAM!$H$27-PARAM!$G$27/2)/(PARAM!$F$27/2-1)) -> -55 | L30: ==PARAM!$F$27/2-1 -> 1
A31: inner top plate - centred on its own two bolt lines, so one part serves both sides | B31: CUT | C31: pl.ti | D31: ==(PARAM!$D$27/2) -> 35 | E31: ==-((PARAM!$C$14/2-PARAM!$H$27-PARAM!$G$27/2)/(PARAM!$F$27/2-1))/2 -> -27.5 | F31: ho.b | G31: ==((PARAM!$D$14/2-PARAM!$E$27-PARAM!$D$27/2)/(PARAM!$C$27/2-1)) -> 75 | H31: 0 | I31: ==PARAM!$C$27/2-1 -> 1 | J31: 0 | K31: ==(PARAM!$C$14/2-PARAM!$H$27-PARAM!$G$27/2)/(PARAM!$F$27/2-1) -> 55 | L31: 1
B32: CUT | C32: pl.ti | D32: ==-(PARAM!$D$27/2) -> -35 | E32: ==-((PARAM!$C$14/2-PARAM!$H$27-PARAM!$G$27/2)/(PARAM!$F$27/2-1))/2 -> -27.5 | F32: ho.b | G32: ==-((PARAM!$D$14/2-PARAM!$E$27-PARAM!$D$27/2)/(PARAM!$C$27/2-1)) -> -75 | H32: 0 | I32: ==PARAM!$C$27/2-1 -> 1 | J32: 0 | K32: ==(PARAM!$C$14/2-PARAM!$H$27-PARAM!$G$27/2)/(PARAM!$F$27/2-1) -> 55 | L32: 1
A33: inner bottom plate - centred on its own two bolt lines, so one part serves both sides | B33: CUT | C33: pl.bi | D33: ==(PARAM!$D$27/2) -> 35 | E33: ==-((PARAM!$C$14/2-PARAM!$H$27-PARAM!$G$27/2)/(PARAM!$F$27/2-1))/2 -> -27.5 | F33: ho.b | G33: ==((PARAM!$D$14/2-PARAM!$E$27-PARAM!$D$27/2)/(PARAM!$C$27/2-1)) -> 75 | H33: 0 | I33: ==PARAM!$C$27/2-1 -> 1 | J33: 0 | K33: ==(PARAM!$C$14/2-PARAM!$H$27-PARAM!$G$27/2)/(PARAM!$F$27/2-1) -> 55 | L33: 1
B34: CUT | C34: pl.bi | D34: ==-(PARAM!$D$27/2) -> -35 | E34: ==-((PARAM!$C$14/2-PARAM!$H$27-PARAM!$G$27/2)/(PARAM!$F$27/2-1))/2 -> -27.5 | F34: ho.b | G34: ==-((PARAM!$D$14/2-PARAM!$E$27-PARAM!$D$27/2)/(PARAM!$C$27/2-1)) -> -75 | H34: 0 | I34: ==PARAM!$C$27/2-1 -> 1 | J34: 0 | K34: ==(PARAM!$C$14/2-PARAM!$H$27-PARAM!$G$27/2)/(PARAM!$F$27/2-1) -> 55 | L34: 1
A35: beam top flange - measured from the plate centre, the joint end is + | B35: CUT | C35: pl.tf | D35: ==PARAM!$C$7/2+PARAM!$J$6/2-PARAM!$D$27/2 -> 875 | E35: ==(PARAM!$G$27/2) -> 50 | F35: ho.b | G35: ==-((PARAM!$D$14/2-PARAM!$E$27-PARAM!$D$27/2)/(PARAM!$C$27/2-1)) -> -75 | H35: 0 | I35: ==PARAM!$C$27/2-1 -> 1 | J35: 0 | K35: ==((PARAM!$C$14/2-PARAM!$H$27-PARAM!$G$27/2)/(PARAM!$F$27/2-1)) -> 55 | L35: ==PARAM!$F$27/2-1 -> 1
B36: CUT | C36: pl.tf | D36: ==PARAM!$C$7/2+PARAM!$J$6/2-PARAM!$D$27/2 -> 875 | E36: ==-(PARAM!$G$27/2) -> -50 | F36: ho.b | G36: ==-((PARAM!$D$14/2-PARAM!$E$27-PARAM!$D$27/2)/(PARAM!$C$27/2-1)) -> -75 | H36: 0 | I36: ==PARAM!$C$27/2-1 -> 1 | J36: 0 | K36: ==-((PARAM!$C$14/2-PARAM!$H$27-PARAM!$G$27/2)/(PARAM!$F$27/2-1)) -> -55 | L36: ==PARAM!$F$27/2-1 -> 1
A37: beam bottom flange - measured from the plate centre, the joint end is + | B37: CUT | C37: pl.bf | D37: ==PARAM!$C$7/2+PARAM!$J$6/2-PARAM!$D$27/2 -> 875 | E37: ==(PARAM!$G$27/2) -> 50 | F37: ho.b | G37: ==-((PARAM!$D$14/2-PARAM!$E$27-PARAM!$D$27/2)/(PARAM!$C$27/2-1)) -> -75 | H37: 0 | I37: ==PARAM!$C$27/2-1 -> 1 | J37: 0 | K37: ==((PARAM!$C$14/2-PARAM!$H$27-PARAM!$G$27/2)/(PARAM!$F$27/2-1)) -> 55 | L37: ==PARAM!$F$27/2-1 -> 1
B38: CUT | C38: pl.bf | D38: ==PARAM!$C$7/2+PARAM!$J$6/2-PARAM!$D$27/2 -> 875 | E38: ==-(PARAM!$G$27/2) -> -50 | F38: ho.b | G38: ==-((PARAM!$D$14/2-PARAM!$E$27-PARAM!$D$27/2)/(PARAM!$C$27/2-1)) -> -75 | H38: 0 | I38: ==PARAM!$C$27/2-1 -> 1 | J38: 0 | K38: ==-((PARAM!$C$14/2-PARAM!$H$27-PARAM!$G$27/2)/(PARAM!$F$27/2-1)) -> -55 | L38: ==PARAM!$F$27/2-1 -> 1
A39: web plate - the depth is one run, no gap at the neutral axis, so two rows not four | B39: CUT | C39: pl.wp | D39: ==(PARAM!$D$28/2) -> 30 | E39: ==-(PARAM!$C$16/2-PARAM!$H$28) -> -70 | F39: ho.b | G39: ==((PARAM!$D$16/2-PARAM!$E$28-PARAM!$D$28/2)/(PARAM!$C$28/2-1)) -> 70 | H39: 0 | I39: ==PARAM!$C$28/2-1 -> 1 | J39: 0 | K39: ==(PARAM!$C$16-2*PARAM!$H$28-PARAM!$G$28)/(PARAM!$F$28-1) -> 70 | L39: ==PARAM!$F$28-1 -> 2
B40: CUT | C40: pl.wp | D40: ==-(PARAM!$D$28/2) -> -30 | E40: ==-(PARAM!$C$16/2-PARAM!$H$28) -> -70 | F40: ho.b | G40: ==-((PARAM!$D$16/2-PARAM!$E$28-PARAM!$D$28/2)/(PARAM!$C$28/2-1)) -> -70 | H40: 0 | I40: ==PARAM!$C$28/2-1 -> 1 | J40: 0 | K40: ==(PARAM!$C$16-2*PARAM!$H$28-PARAM!$G$28)/(PARAM!$F$28-1) -> 70 | L40: ==PARAM!$F$28-1 -> 2
A41: the disc sits on the far corner of the square, leaving the fillet | B41: CUT | C41: pl.fil | D41: ==PARAM!$H$6/2 -> 9 | E41: ==-PARAM!$H$6/2 -> -9 | F41: ho.fil
A42: beam web - one member | B42: CUT | C42: pl.wb | D42: ==PARAM!$C$7/2+PARAM!$J$6/2-PARAM!$D$28/2-((PARAM!$D$16/2-PARAM!$E$28-PARAM!$D$28/2)/(PARAM!$C$28/2-1))*(PARAM!$C$28/2-1) -> 810 | E42: ==-(PARAM!$C$16/2-PARAM!$H$28) -> -70 | F42: ho.b | G42: ==(PARAM!$D$16/2-PARAM!$E$28-PARAM!$D$28/2)/(PARAM!$C$28/2-1) -> 70 | H42: 0 | I42: ==PARAM!$C$28/2-1 -> 1 | J42: 0 | K42: ==(PARAM!$C$16-2*PARAM!$H$28-PARAM!$G$28)/(PARAM!$F$28-1) -> 70 | L42: ==PARAM!$F$28-1 -> 2
A44: MODULE id member ref.pt L.X L.Y L.Z PLANE [ROT.X ROT.Y ROT.Z]
A45: Every coordinate below is the real one, measured from the joint centre. A module is placed by its BASE point, so each ASSY row further down repeats that point - which lands the module exactly where these rows say.
...
